Traceback (most recent call last):
  File "/opt/hostedtoolcache/Python/3.10.11/x64/lib/python3.10/site-packages/jupyter_cache/executors/utils.py", line 58, in single_nb_execution
    executenb(
  File "/opt/hostedtoolcache/Python/3.10.11/x64/lib/python3.10/site-packages/nbclient/client.py", line 1305, in execute
    return NotebookClient(nb=nb, resources=resources, km=km, **kwargs).execute()
  File "/opt/hostedtoolcache/Python/3.10.11/x64/lib/python3.10/site-packages/jupyter_core/utils/__init__.py", line 166, in wrapped
    return loop.run_until_complete(inner)
  File "/opt/hostedtoolcache/Python/3.10.11/x64/lib/python3.10/asyncio/base_events.py", line 649, in run_until_complete
    return future.result()
  File "/opt/hostedtoolcache/Python/3.10.11/x64/lib/python3.10/site-packages/nbclient/client.py", line 705, in async_execute
    await self.async_execute_cell(
  File "/opt/hostedtoolcache/Python/3.10.11/x64/lib/python3.10/site-packages/nbclient/client.py", line 1058, in async_execute_cell
    await self._check_raise_for_error(cell, cell_index, exec_reply)
  File "/opt/hostedtoolcache/Python/3.10.11/x64/lib/python3.10/site-packages/nbclient/client.py", line 914, in _check_raise_for_error
    raise CellExecutionError.from_cell_and_msg(cell, exec_reply_content)
nbclient.exceptions.CellExecutionError: An error occurred while executing the following cell:
------------------
n_max = 50
ns = np.arange(2, n_max, 1, dtype=np.int)
tr = np.zeros(len(ns))

for i, n in enumerate(ns):
    xi = np.linspace(0, 2, n)
    yi = fkt(xi)
    tr[i] = scipy.integrate.trapz(yi, xi)
------------------


[0;31m---------------------------------------------------------------------------[0m
[0;31mAttributeError[0m                            Traceback (most recent call last)
Cell [0;32mIn[6], line 2[0m
[1;32m      1[0m n_max [38;5;241m=[39m [38;5;241m50[39m
[0;32m----> 2[0m ns [38;5;241m=[39m np[38;5;241m.[39marange([38;5;241m2[39m, n_max, [38;5;241m1[39m, dtype[38;5;241m=[39m[43mnp[49m[38;5;241;43m.[39;49m[43mint[49m)
[1;32m      3[0m tr [38;5;241m=[39m np[38;5;241m.[39mzeros([38;5;28mlen[39m(ns))
[1;32m      5[0m [38;5;28;01mfor[39;00m i, n [38;5;129;01min[39;00m [38;5;28menumerate[39m(ns):

File [0;32m/opt/hostedtoolcache/Python/3.10.11/x64/lib/python3.10/site-packages/numpy/__init__.py:305[0m, in [0;36m__getattr__[0;34m(attr)[0m
[1;32m    300[0m     warnings[38;5;241m.[39mwarn(
[1;32m    301[0m         [38;5;124mf[39m[38;5;124m"[39m[38;5;124mIn the future `np.[39m[38;5;132;01m{[39;00mattr[38;5;132;01m}[39;00m[38;5;124m` will be defined as the [39m[38;5;124m"[39m
[1;32m    302[0m         [38;5;124m"[39m[38;5;124mcorresponding NumPy scalar.[39m[38;5;124m"[39m, [38;5;167;01mFutureWarning[39;00m, stacklevel[38;5;241m=[39m[38;5;241m2[39m)
[1;32m    304[0m [38;5;28;01mif[39;00m attr [38;5;129;01min[39;00m __former_attrs__:
[0;32m--> 305[0m     [38;5;28;01mraise[39;00m [38;5;167;01mAttributeError[39;00m(__former_attrs__[attr])
[1;32m    307[0m [38;5;66;03m# Importing Tester requires importing all of UnitTest which is not a[39;00m
[1;32m    308[0m [38;5;66;03m# cheap import Since it is mainly used in test suits, we lazy import it[39;00m
[1;32m    309[0m [38;5;66;03m# here to save on the order of 10 ms of import time for most users[39;00m
[1;32m    310[0m [38;5;66;03m#[39;00m
[1;32m    311[0m [38;5;66;03m# The previous way Tester was imported also had a side effect of adding[39;00m
[1;32m    312[0m [38;5;66;03m# the full `numpy.testing` namespace[39;00m
[1;32m    313[0m [38;5;28;01mif[39;00m attr [38;5;241m==[39m [38;5;124m'[39m[38;5;124mtesting[39m[38;5;124m'[39m:

[0;31mAttributeError[0m: module 'numpy' has no attribute 'int'.
`np.int` was a deprecated alias for the builtin `int`. To avoid this error in existing code, use `int` by itself. Doing this will not modify any behavior and is safe. When replacing `np.int`, you may wish to use e.g. `np.int64` or `np.int32` to specify the precision. If you wish to review your current use, check the release note link for additional information.
The aliases was originally deprecated in NumPy 1.20; for more details and guidance see the original release note at:
    https://numpy.org/devdocs/release/1.20.0-notes.html#deprecations

