Traceback (most recent call last):
  File "/opt/hostedtoolcache/Python/3.10.12/x64/lib/python3.10/site-packages/jupyter_cache/executors/utils.py", line 58, in single_nb_execution
    executenb(
  File "/opt/hostedtoolcache/Python/3.10.12/x64/lib/python3.10/site-packages/nbclient/client.py", line 1305, in execute
    return NotebookClient(nb=nb, resources=resources, km=km, **kwargs).execute()
  File "/opt/hostedtoolcache/Python/3.10.12/x64/lib/python3.10/site-packages/jupyter_core/utils/__init__.py", line 166, in wrapped
    return loop.run_until_complete(inner)
  File "/opt/hostedtoolcache/Python/3.10.12/x64/lib/python3.10/asyncio/base_events.py", line 649, in run_until_complete
    return future.result()
  File "/opt/hostedtoolcache/Python/3.10.12/x64/lib/python3.10/site-packages/nbclient/client.py", line 705, in async_execute
    await self.async_execute_cell(
  File "/opt/hostedtoolcache/Python/3.10.12/x64/lib/python3.10/site-packages/nbclient/client.py", line 1058, in async_execute_cell
    await self._check_raise_for_error(cell, cell_index, exec_reply)
  File "/opt/hostedtoolcache/Python/3.10.12/x64/lib/python3.10/site-packages/nbclient/client.py", line 914, in _check_raise_for_error
    raise CellExecutionError.from_cell_and_msg(cell, exec_reply_content)
nbclient.exceptions.CellExecutionError: An error occurred while executing the following cell:
------------------
n_max = 50000
dn = 250
ns = np.arange(dn, n_max, dn, dtype=np.int)
mc = np.zeros(len(ns))

xi = np.zeros(n_max)

for i, n in enumerate(ns):
    xi[n-dn:n] = np.random.random(dn) * 2
    yi = fkt(xi[:n])
    mc[i] = 2 * 1/n * np.sum(yi)
------------------


[0;31m---------------------------------------------------------------------------[0m
[0;31mAttributeError[0m                            Traceback (most recent call last)
Cell [0;32mIn[4], line 3[0m
[1;32m      1[0m n_max [38;5;241m=[39m [38;5;241m50000[39m
[1;32m      2[0m dn [38;5;241m=[39m [38;5;241m250[39m
[0;32m----> 3[0m ns [38;5;241m=[39m np[38;5;241m.[39marange(dn, n_max, dn, dtype[38;5;241m=[39m[43mnp[49m[38;5;241;43m.[39;49m[43mint[49m)
[1;32m      4[0m mc [38;5;241m=[39m np[38;5;241m.[39mzeros([38;5;28mlen[39m(ns))
[1;32m      6[0m xi [38;5;241m=[39m np[38;5;241m.[39mzeros(n_max)

File [0;32m/opt/hostedtoolcache/Python/3.10.12/x64/lib/python3.10/site-packages/numpy/__init__.py:313[0m, in [0;36m__getattr__[0;34m(attr)[0m
[1;32m    308[0m     warnings[38;5;241m.[39mwarn(
[1;32m    309[0m         [38;5;124mf[39m[38;5;124m"[39m[38;5;124mIn the future `np.[39m[38;5;132;01m{[39;00mattr[38;5;132;01m}[39;00m[38;5;124m` will be defined as the [39m[38;5;124m"[39m
[1;32m    310[0m         [38;5;124m"[39m[38;5;124mcorresponding NumPy scalar.[39m[38;5;124m"[39m, [38;5;167;01mFutureWarning[39;00m, stacklevel[38;5;241m=[39m[38;5;241m2[39m)
[1;32m    312[0m [38;5;28;01mif[39;00m attr [38;5;129;01min[39;00m __former_attrs__:
[0;32m--> 313[0m     [38;5;28;01mraise[39;00m [38;5;167;01mAttributeError[39;00m(__former_attrs__[attr])
[1;32m    315[0m [38;5;28;01mif[39;00m attr [38;5;241m==[39m [38;5;124m'[39m[38;5;124mtesting[39m[38;5;124m'[39m:
[1;32m    316[0m     [38;5;28;01mimport[39;00m [38;5;21;01mnumpy[39;00m[38;5;21;01m.[39;00m[38;5;21;01mtesting[39;00m [38;5;28;01mas[39;00m [38;5;21;01mtesting[39;00m

[0;31mAttributeError[0m: module 'numpy' has no attribute 'int'.
`np.int` was a deprecated alias for the builtin `int`. To avoid this error in existing code, use `int` by itself. Doing this will not modify any behavior and is safe. When replacing `np.int`, you may wish to use e.g. `np.int64` or `np.int32` to specify the precision. If you wish to review your current use, check the release note link for additional information.
The aliases was originally deprecated in NumPy 1.20; for more details and guidance see the original release note at:
    https://numpy.org/devdocs/release/1.20.0-notes.html#deprecations

