Traceback (most recent call last):
  File "/opt/hostedtoolcache/Python/3.10.16/x64/lib/python3.10/site-packages/jupyter_cache/executors/utils.py", line 58, in single_nb_execution
    executenb(
  File "/opt/hostedtoolcache/Python/3.10.16/x64/lib/python3.10/site-packages/nbclient/client.py", line 1319, in execute
    return NotebookClient(nb=nb, resources=resources, km=km, **kwargs).execute()
  File "/opt/hostedtoolcache/Python/3.10.16/x64/lib/python3.10/site-packages/jupyter_core/utils/__init__.py", line 165, in wrapped
    return loop.run_until_complete(inner)
  File "/opt/hostedtoolcache/Python/3.10.16/x64/lib/python3.10/asyncio/base_events.py", line 649, in run_until_complete
    return future.result()
  File "/opt/hostedtoolcache/Python/3.10.16/x64/lib/python3.10/site-packages/nbclient/client.py", line 709, in async_execute
    await self.async_execute_cell(
  File "/opt/hostedtoolcache/Python/3.10.16/x64/lib/python3.10/site-packages/nbclient/client.py", line 1062, in async_execute_cell
    await self._check_raise_for_error(cell, cell_index, exec_reply)
  File "/opt/hostedtoolcache/Python/3.10.16/x64/lib/python3.10/site-packages/nbclient/client.py", line 918, in _check_raise_for_error
    raise CellExecutionError.from_cell_and_msg(cell, exec_reply_content)
nbclient.exceptions.CellExecutionError: An error occurred while executing the following cell:
------------------
import matplotlib.pyplot as plt
import numpy as np
import scipy as sp
from scipy import integrate

def fkt(xi):
    yi = np.sin(xi)
    return yi

def trapez(werte, schrittweite):
    flaeche = 0
    for i in range(len(werte)-1):
        flaeche += werte[i] * schrittweite
        flaeche += (werte[i+1] - werte[i]) * schrittweite / 2
    return flaeche

xi = np.arange(0,2*np.pi,0.2)
yi = fkt(xi)

flaeche_sp = sp.integrate.trapz(yi, xi)
flaeche_selbst = trapez(yi, 0.2)

print('Eigene Trapezfunktion:', flaeche_selbst)
print('Scipy:', flaeche_sp)
------------------


[0;31m---------------------------------------------------------------------------[0m
[0;31mAttributeError[0m                            Traceback (most recent call last)
Cell [0;32mIn[1], line 20[0m
[1;32m     17[0m xi [38;5;241m=[39m np[38;5;241m.[39marange([38;5;241m0[39m,[38;5;241m2[39m[38;5;241m*[39mnp[38;5;241m.[39mpi,[38;5;241m0.2[39m)
[1;32m     18[0m yi [38;5;241m=[39m fkt(xi)
[0;32m---> 20[0m flaeche_sp [38;5;241m=[39m [43msp[49m[38;5;241;43m.[39;49m[43mintegrate[49m[38;5;241;43m.[39;49m[43mtrapz[49m(yi, xi)
[1;32m     21[0m flaeche_selbst [38;5;241m=[39m trapez(yi, [38;5;241m0.2[39m)
[1;32m     23[0m [38;5;28mprint[39m([38;5;124m'[39m[38;5;124mEigene Trapezfunktion:[39m[38;5;124m'[39m, flaeche_selbst)

[0;31mAttributeError[0m: module 'scipy.integrate' has no attribute 'trapz'

